2024-11-08 18:06:56,689 Exception occurred: {'status': 1, 'message': 'Expecting value: line 1 column 1 (char 0)'}
Traceback (most recent call last):
  File "C:\Users\rickz\OneDrive\Desktop\Projects\Apps\HQ App\HQ_api\Hq_api.py", line 49, in handle_sales
    datas = json.loads(request.data)
            ^^^^^^^^^^^^^^^^^^^^^^^^
  File "C:\Users\rickz\AppData\Local\Programs\Python\Python312\Lib\json\__init__.py", line 346, in loads
    return _default_decoder.decode(s)
           ^^^^^^^^^^^^^^^^^^^^^^^^^^
  File "C:\Users\rickz\AppData\Local\Programs\Python\Python312\Lib\json\decoder.py", line 337, in decode
    obj, end = self.raw_decode(s, idx=_w(s, 0).end())
               ^^^^^^^^^^^^^^^^^^^^^^^^^^^^^^^^^^^^^^
  File "C:\Users\rickz\AppData\Local\Programs\Python\Python312\Lib\json\decoder.py", line 355, in raw_decode
    raise JSONDecodeError("Expecting value", s, err.value) from None
json.decoder.JSONDecodeError: Expecting value: line 1 column 1 (char 0)
2024-11-08 18:06:57,711 Exception occurred: {'status': 1, 'message': 'Expecting value: line 1 column 1 (char 0)'}
Traceback (most recent call last):
  File "C:\Users\rickz\OneDrive\Desktop\Projects\Apps\HQ App\HQ_api\Hq_api.py", line 49, in handle_sales
    datas = json.loads(request.data)
            ^^^^^^^^^^^^^^^^^^^^^^^^
  File "C:\Users\rickz\AppData\Local\Programs\Python\Python312\Lib\json\__init__.py", line 346, in loads
    return _default_decoder.decode(s)
           ^^^^^^^^^^^^^^^^^^^^^^^^^^
  File "C:\Users\rickz\AppData\Local\Programs\Python\Python312\Lib\json\decoder.py", line 337, in decode
    obj, end = self.raw_decode(s, idx=_w(s, 0).end())
               ^^^^^^^^^^^^^^^^^^^^^^^^^^^^^^^^^^^^^^
  File "C:\Users\rickz\AppData\Local\Programs\Python\Python312\Lib\json\decoder.py", line 355, in raw_decode
    raise JSONDecodeError("Expecting value", s, err.value) from None
json.decoder.JSONDecodeError: Expecting value: line 1 column 1 (char 0)
2024-11-08 18:12:01,776 Exception occurred: {'status': 1, 'message': '[WinError 10054] An existing connection was forcibly closed by the remote host'}
Traceback (most recent call last):
  File "C:\Users\rickz\OneDrive\Desktop\Projects\Apps\HQ App\HQ_api\Hq_api.py", line 62, in handle_maintenance
    datas = json.loads(request.data)
                       ^^^^^^^^^^^^
  File "C:\Users\rickz\AppData\Local\Programs\Python\Python312\Lib\site-packages\werkzeug\utils.py", line 107, in __get__
    value = self.fget(obj)  # type: ignore
            ^^^^^^^^^^^^^^
  File "C:\Users\rickz\AppData\Local\Programs\Python\Python312\Lib\site-packages\werkzeug\wrappers\request.py", line 370, in data
    return self.get_data(parse_form_data=True)
           ^^^^^^^^^^^^^^^^^^^^^^^^^^^^^^^^^^^
  File "C:\Users\rickz\AppData\Local\Programs\Python\Python312\Lib\site-packages\werkzeug\wrappers\request.py", line 419, in get_data
    rv = self.stream.read()
         ^^^^^^^^^^^^^^^^^^
  File "C:\Users\rickz\AppData\Local\Programs\Python\Python312\Lib\site-packages\gevent\pywsgi.py", line 434, in read
    return self._do_read(length)
           ^^^^^^^^^^^^^^^^^^^^^
  File "C:\Users\rickz\AppData\Local\Programs\Python\Python312\Lib\site-packages\gevent\pywsgi.py", line 217, in _do_read
    read = reader(length)
           ^^^^^^^^^^^^^^
  File "C:\Users\rickz\AppData\Local\Programs\Python\Python312\Lib\socket.py", line 707, in readinto
    return self._sock.recv_into(b)
           ^^^^^^^^^^^^^^^^^^^^^^^
  File "C:\Users\rickz\AppData\Local\Programs\Python\Python312\Lib\site-packages\gevent\_socketcommon.py", line 691, in recv_into
    return self._sock.recv_into(*args)
           ^^^^^^^^^^^^^^^^^^^^^^^^^^^
ConnectionResetError: [WinError 10054] An existing connection was forcibly closed by the remote host
2024-11-08 18:19:07,874 Exception occurred: {'status': 1, 'message': '[WinError 10054] An existing connection was forcibly closed by the remote host'}
Traceback (most recent call last):
  File "C:\Users\rickz\OneDrive\Desktop\Projects\Apps\HQ App\HQ_api\Hq_api.py", line 62, in handle_maintenance
    datas = json.loads(request.data)
                       ^^^^^^^^^^^^
  File "C:\Users\rickz\AppData\Local\Programs\Python\Python312\Lib\site-packages\werkzeug\utils.py", line 107, in __get__
    value = self.fget(obj)  # type: ignore
            ^^^^^^^^^^^^^^
  File "C:\Users\rickz\AppData\Local\Programs\Python\Python312\Lib\site-packages\werkzeug\wrappers\request.py", line 370, in data
    return self.get_data(parse_form_data=True)
           ^^^^^^^^^^^^^^^^^^^^^^^^^^^^^^^^^^^
  File "C:\Users\rickz\AppData\Local\Programs\Python\Python312\Lib\site-packages\werkzeug\wrappers\request.py", line 419, in get_data
    rv = self.stream.read()
         ^^^^^^^^^^^^^^^^^^
  File "C:\Users\rickz\AppData\Local\Programs\Python\Python312\Lib\site-packages\gevent\pywsgi.py", line 434, in read
    return self._do_read(length)
           ^^^^^^^^^^^^^^^^^^^^^
  File "C:\Users\rickz\AppData\Local\Programs\Python\Python312\Lib\site-packages\gevent\pywsgi.py", line 217, in _do_read
    read = reader(length)
           ^^^^^^^^^^^^^^
  File "C:\Users\rickz\AppData\Local\Programs\Python\Python312\Lib\socket.py", line 707, in readinto
    return self._sock.recv_into(b)
           ^^^^^^^^^^^^^^^^^^^^^^^
  File "C:\Users\rickz\AppData\Local\Programs\Python\Python312\Lib\site-packages\gevent\_socketcommon.py", line 691, in recv_into
    return self._sock.recv_into(*args)
           ^^^^^^^^^^^^^^^^^^^^^^^^^^^
ConnectionResetError: [WinError 10054] An existing connection was forcibly closed by the remote host
